<?xml version="1.0" ?>
<!-- =================================================================================== -->
<!-- |    This document was autogenerated by xacro from /home/tmarkmann/dexmo/augmented-dexmo/ros/src/human_arm_description/robots/human_arm.urdf.xacro | -->
<!-- |    EDITING THIS FILE BY HAND IS NOT RECOMMENDED                                 | -->
<!-- =================================================================================== -->
<robot name="human_arm">
    <!--
	    HUMAN ARM MODEL v 0.1
	    urdf derived from human Pisa SoftHand
	    author David Leins
	    meshes from GrabCAD, author Joerg Schmit
	    original CAD model available at: https://grabcad.com/library/human-left-hand/
	-->
    <material name="HumanHand/Skin">
        <color rgba="0.802 0.732 0.673 1.0" />
    </material>
    <link name="forearm_base" />
    <!-- ELBOW -->
    <joint name="elbow_joint" type="revolute">
        <origin rpy="0 0 0" xyz="0 0 0" />
        <axis xyz="-1 0 0" />
        <limit effort="100" lower="-0.3839724354387525" upper="1.5707963267948966" velocity="100" />
        <dynamics damping="0.0" friction="0.0" />
        <parent link="forearm_base" />
        <child link="forearm_link" />
    </joint>
    <link name="forearm_link">
        <visual>
            <geometry>
                <mesh filename="package://human_arm_description/model/meshes/forearm.stl" scale="0.001 0.001 0.001" />
            </geometry>
            <material name="HumanHand/Skin" />
        </visual>
    </link>
    <!-- WRIST (Supination/Pronation) -->
    <joint name="distal_radioulnar_joint" type="revolute">
        <origin rpy="0 0 0" xyz="0 0.05055 0.2729" />
        <axis xyz="0 0 -1" />
        <limit effort="100" lower="-0.17453292519943295" upper="3.141592653589793" velocity="100" />
        <dynamics damping="0.0" friction="0.0" />
        <parent link="forearm_link" />
        <child link="distal_radioulnar_link" />
    </joint>
    <link name="distal_radioulnar_link" />
    <!-- WRIST (Radial/Ulnar abduction) -->
    <joint name="radiocarpal_abductor_joint" type="revolute">
        <axis xyz="0 -1 0" />
        <limit effort="100" lower="-0.08726646259971647" upper="0.5235987755982988" velocity="100" />
        <dynamics damping="0.0" friction="0.0" />
        <origin rpy="0 0 0" xyz="0 0 0" />
        <parent link="distal_radioulnar_link" />
        <child link="palm_abductor_link" />
    </joint>
    <link name="palm_abductor_link" />
    <!-- WRIST (Palmar/Dorsal) Flexion -->
    <joint name="radiocarpal_flexor_joint" type="revolute">
        <axis xyz="-1 0 0" />
        <limit effort="100" lower="-1.2217304763960306" upper="1.0471975511965976" velocity="100" />
        <dynamics damping="0.0" friction="0.0" />
        <origin rpy="0 0 0" xyz="0 0 0" />
        <parent link="palm_abductor_link" />
        <child link="palm_link" />
    </joint>
    <link name="palm_link">
        <visual>
            <geometry>
                <mesh filename="package://human_arm_description/model/meshes/palm.stl" scale="0.001 0.001 0.001" />
            </geometry>
            <material name="HumanHand/Skin" />
        </visual>
    </link>
    <!-- THUMB AND FINGERS -->
    <!-- KNUCKLE -->
    <joint name="thumb_abduction_joint" type="revolute">
        <origin rpy="0.0 0.624 0" xyz="0.02475 -0.0125 0.0125" />
        <parent link="palm_link" />
        <child link="thumb_knuckle_link" />
        <axis xyz="1 0 0" />
        <limit effort="100" lower="-0.5410520681182421" upper="1.0681415022205296" velocity="100" />
        <dynamics damping="0.0" friction="0.0" />
    </joint>
    <link name="thumb_knuckle_link" />
    <!-- PROXIMAL PHALANGE -->
    <joint name="thumb_proximal_joint" type="revolute">
        <origin rpy="0 0 0" xyz="0 0 0" />
        <parent link="thumb_knuckle_link" />
        <child link="thumb_proximal_link" />
        <axis xyz="0 -1 0" />
        <limit effort="100" lower="-0.4698426346368736" upper="0.45989425790050587" velocity="100" />
        <dynamics damping="0.0" friction="0.0" />
    </joint>
    <link name="thumb_proximal_link">
        <visual>
            <geometry>
                <mesh filename="package://human_arm_description/model/meshes/thumb_proximal.stl" scale="0.001 0.001 0.001" />
            </geometry>
            <material name="HumanHand/Skin" />
        </visual>
    </link>
    <!-- MIDDLE PHALANGE -->
    <joint name="thumb_middle_joint" type="revolute">
        <origin rpy="0 0 0" xyz="0 0 0.05415" />
        <parent link="thumb_proximal_link" />
        <child link="thumb_middle_link" />
        <axis xyz="0 -1 0" />
        <limit effort="100" lower="-0.07679448708775051" upper="1.0471975511965976" velocity="100" />
        <dynamics damping="0.0" friction="0.0" />
    </joint>
    <link name="thumb_middle_link">
        <visual>
            <geometry>
                <mesh filename="package://human_arm_description/model/meshes/thumb_middle.stl" scale="0.001 0.001 0.001" />
            </geometry>
            <material name="HumanHand/Skin" />
        </visual>
    </link>
    <!-- DISTAL PHALANGE -->
    <joint name="thumb_distal_joint" type="revolute">
        <origin rpy="0 0 0" xyz="0 0 0.03803" />
        <parent link="thumb_middle_link" />
        <child link="thumb_distal_link" />
        <axis xyz="0 -1 0" />
        <limit effort="100" lower="-0.20943951023931953" upper="1.53588974175501" velocity="100" />
        <dynamics damping="0.0" friction="0.0" />
    </joint>
    <link name="thumb_distal_link">
        <visual>
            <geometry>
                <mesh filename="package://human_arm_description/model/meshes/thumb_distal.stl" scale="0.001 0.001 0.001" />
            </geometry>
            <material name="HumanHand/Skin" />
        </visual>
    </link>
    <!-- TIP-->
    <joint name="thumb_ee_joint" type="fixed">
        <origin rpy="0 0 0" xyz="0 0 0.03" />
        <parent link="thumb_distal_link" />
        <child link="thumb_ee_link" />
    </joint>
    <link name="thumb_ee_link" />
    <!-- KNUCKLE -->
    <joint name="index_abduction_joint" type="revolute">
        <origin rpy="0 0 0" xyz="0.02175 -0.002 0.099" />
        <parent link="palm_link" />
        <child link="index_knuckle_link" />
        <axis xyz="0 -1 0" />
        <limit effort="100" lower="-0.3490658503988659" upper="0.3490658503988659" velocity="100" />
        <dynamics damping="0.0" friction="0.0" />
    </joint>
    <link name="index_knuckle_link" />
    <!-- PROXIMAL PHALANGE -->
    <joint name="index_proximal_joint" type="revolute">
        <origin rpy="0 0 0" xyz="0 0 0" />
        <parent link="index_knuckle_link" />
        <child link="index_proximal_link" />
        <axis xyz="1 0 0" />
        <limit effort="100" lower="0.0" upper="1.5707963267948966" velocity="100" />
        <dynamics damping="0.0" friction="0.0" />
    </joint>
    <link name="index_proximal_link">
        <visual>
            <geometry>
                <mesh filename="package://human_arm_description/model/meshes/index_proximal.stl" scale="0.001 0.001 0.001" />
            </geometry>
            <material name="HumanHand/Skin" />
        </visual>
    </link>
    <!-- MIDDLE PHALANGE -->
    <joint name="index_middle_joint" type="revolute">
        <origin rpy="0 0 0" xyz="0 0 0.046" />
        <parent link="index_proximal_link" />
        <child link="index_middle_link" />
        <axis xyz="1 0 0" />
        <limit effort="100" lower="0.0" upper="2.1816615649929116" velocity="100" />
        <dynamics damping="0.0" friction="0.0" />
    </joint>
    <link name="index_middle_link">
        <visual>
            <geometry>
                <mesh filename="package://human_arm_description/model/meshes/index_middle.stl" scale="0.001 0.001 0.001" />
            </geometry>
            <material name="HumanHand/Skin" />
        </visual>
    </link>
    <!-- DISTAL PHALANGE -->
    <joint name="index_distal_joint" type="revolute">
        <origin rpy="0 0 0" xyz="0 0 0.027" />
        <parent link="index_middle_link" />
        <child link="index_distal_link" />
        <axis xyz="1 0 0" />
        <limit effort="100" lower="0.0" upper="1.5707963267948966" velocity="100" />
        <dynamics damping="0.0" friction="0.0" />
    </joint>
    <link name="index_distal_link">
        <visual>
            <geometry>
                <mesh filename="package://human_arm_description/model/meshes/index_distal.stl" scale="0.001 0.001 0.001" />
            </geometry>
            <material name="HumanHand/Skin" />
        </visual>
    </link>
    <!-- TIP-->
    <joint name="index_ee_joint" type="fixed">
        <origin rpy="0 0 0" xyz="0 0 0.03" />
        <parent link="index_distal_link" />
        <child link="index_ee_link" />
    </joint>
    <link name="index_ee_link" />
    <!-- KNUCKLE -->
    <joint name="middle_abduction_joint" type="revolute">
        <origin rpy="0 0 0" xyz="-0.002 0.0015 0.0955" />
        <parent link="palm_link" />
        <child link="middle_knuckle_link" />
        <axis xyz="0 -1 0" />
        <limit effort="100" lower="-0.3490658503988659" upper="0.3490658503988659" velocity="100" />
        <dynamics damping="0.0" friction="0.0" />
    </joint>
    <link name="middle_knuckle_link" />
    <!-- PROXIMAL PHALANGE -->
    <joint name="middle_proximal_joint" type="revolute">
        <origin rpy="0 0 0" xyz="0 0 0" />
        <parent link="middle_knuckle_link" />
        <child link="middle_proximal_link" />
        <axis xyz="1 0 0" />
        <limit effort="100" lower="0.0" upper="1.5707963267948966" velocity="100" />
        <dynamics damping="0.0" friction="0.0" />
    </joint>
    <link name="middle_proximal_link">
        <visual>
            <geometry>
                <mesh filename="package://human_arm_description/model/meshes/middle_proximal.stl" scale="0.001 0.001 0.001" />
            </geometry>
            <material name="HumanHand/Skin" />
        </visual>
    </link>
    <!-- MIDDLE PHALANGE -->
    <joint name="middle_middle_joint" type="revolute">
        <origin rpy="0 0 0" xyz="0 0 0.0495" />
        <parent link="middle_proximal_link" />
        <child link="middle_middle_link" />
        <axis xyz="1 0 0" />
        <limit effort="100" lower="0.0" upper="2.1816615649929116" velocity="100" />
        <dynamics damping="0.0" friction="0.0" />
    </joint>
    <link name="middle_middle_link">
        <visual>
            <geometry>
                <mesh filename="package://human_arm_description/model/meshes/middle_middle.stl" scale="0.001 0.001 0.001" />
            </geometry>
            <material name="HumanHand/Skin" />
        </visual>
    </link>
    <!-- DISTAL PHALANGE -->
    <joint name="middle_distal_joint" type="revolute">
        <origin rpy="0 0 0" xyz="0 0 0.033" />
        <parent link="middle_middle_link" />
        <child link="middle_distal_link" />
        <axis xyz="1 0 0" />
        <limit effort="100" lower="0.0" upper="1.5707963267948966" velocity="100" />
        <dynamics damping="0.0" friction="0.0" />
    </joint>
    <link name="middle_distal_link">
        <visual>
            <geometry>
                <mesh filename="package://human_arm_description/model/meshes/middle_distal.stl" scale="0.001 0.001 0.001" />
            </geometry>
            <material name="HumanHand/Skin" />
        </visual>
    </link>
    <!-- TIP-->
    <joint name="middle_ee_joint" type="fixed">
        <origin rpy="0 0 0" xyz="0 0 0.03" />
        <parent link="middle_distal_link" />
        <child link="middle_ee_link" />
    </joint>
    <link name="middle_ee_link" />
    <!-- KNUCKLE -->
    <joint name="ring_abduction_joint" type="revolute">
        <origin rpy="0 0 0" xyz="-0.02225 0.001 0.09" />
        <parent link="palm_link" />
        <child link="ring_knuckle_link" />
        <axis xyz="0 -1 0" />
        <limit effort="100" lower="-0.3490658503988659" upper="0.3490658503988659" velocity="100" />
        <dynamics damping="0.0" friction="0.0" />
    </joint>
    <link name="ring_knuckle_link" />
    <!-- PROXIMAL PHALANGE -->
    <joint name="ring_proximal_joint" type="revolute">
        <origin rpy="0 0 0" xyz="0 0 0" />
        <parent link="ring_knuckle_link" />
        <child link="ring_proximal_link" />
        <axis xyz="1 0 0" />
        <limit effort="100" lower="0.0" upper="1.5707963267948966" velocity="100" />
        <dynamics damping="0.0" friction="0.0" />
    </joint>
    <link name="ring_proximal_link">
        <visual>
            <geometry>
                <mesh filename="package://human_arm_description/model/meshes/ring_proximal.stl" scale="0.001 0.001 0.001" />
            </geometry>
            <material name="HumanHand/Skin" />
        </visual>
    </link>
    <!-- MIDDLE PHALANGE -->
    <joint name="ring_middle_joint" type="revolute">
        <origin rpy="0 0 0" xyz="0 0 0.048" />
        <parent link="ring_proximal_link" />
        <child link="ring_middle_link" />
        <axis xyz="1 0 0" />
        <limit effort="100" lower="0.0" upper="2.1816615649929116" velocity="100" />
        <dynamics damping="0.0" friction="0.0" />
    </joint>
    <link name="ring_middle_link">
        <visual>
            <geometry>
                <mesh filename="package://human_arm_description/model/meshes/ring_middle.stl" scale="0.001 0.001 0.001" />
            </geometry>
            <material name="HumanHand/Skin" />
        </visual>
    </link>
    <!-- DISTAL PHALANGE -->
    <joint name="ring_distal_joint" type="revolute">
        <origin rpy="0 0 0" xyz="0 0 0.033" />
        <parent link="ring_middle_link" />
        <child link="ring_distal_link" />
        <axis xyz="1 0 0" />
        <limit effort="100" lower="0.0" upper="1.5707963267948966" velocity="100" />
        <dynamics damping="0.0" friction="0.0" />
    </joint>
    <link name="ring_distal_link">
        <visual>
            <geometry>
                <mesh filename="package://human_arm_description/model/meshes/ring_distal.stl" scale="0.001 0.001 0.001" />
            </geometry>
            <material name="HumanHand/Skin" />
        </visual>
    </link>
    <!-- TIP-->
    <joint name="ring_ee_joint" type="fixed">
        <origin rpy="0 0 0" xyz="0 0 0.03" />
        <parent link="ring_distal_link" />
        <child link="ring_ee_link" />
    </joint>
    <link name="ring_ee_link" />
    <!-- KNUCKLE -->
    <joint name="little_abduction_joint" type="revolute">
        <origin rpy="0 0 0" xyz="-0.04175 -0.003 0.079" />
        <parent link="palm_link" />
        <child link="little_knuckle_link" />
        <axis xyz="0 -1 0" />
        <limit effort="100" lower="-0.3490658503988659" upper="0.3490658503988659" velocity="100" />
        <dynamics damping="0.0" friction="0.0" />
    </joint>
    <link name="little_knuckle_link" />
    <!-- PROXIMAL PHALANGE -->
    <joint name="little_proximal_joint" type="revolute">
        <origin rpy="0 0 0" xyz="0 0 0" />
        <parent link="little_knuckle_link" />
        <child link="little_proximal_link" />
        <axis xyz="1 0 0" />
        <limit effort="100" lower="0.0" upper="1.5707963267948966" velocity="100" />
        <dynamics damping="0.0" friction="0.0" />
    </joint>
    <link name="little_proximal_link">
        <visual>
            <geometry>
                <mesh filename="package://human_arm_description/model/meshes/little_proximal.stl" scale="0.001 0.001 0.001" />
            </geometry>
            <material name="HumanHand/Skin" />
        </visual>
    </link>
    <!-- MIDDLE PHALANGE -->
    <joint name="little_middle_joint" type="revolute">
        <origin rpy="0 0 0" xyz="0 0 0.037" />
        <parent link="little_proximal_link" />
        <child link="little_middle_link" />
        <axis xyz="1 0 0" />
        <limit effort="100" lower="0.0" upper="2.1816615649929116" velocity="100" />
        <dynamics damping="0.0" friction="0.0" />
    </joint>
    <link name="little_middle_link">
        <visual>
            <geometry>
                <mesh filename="package://human_arm_description/model/meshes/little_middle.stl" scale="0.001 0.001 0.001" />
            </geometry>
            <material name="HumanHand/Skin" />
        </visual>
    </link>
    <!-- DISTAL PHALANGE -->
    <joint name="little_distal_joint" type="revolute">
        <origin rpy="0 0 0" xyz="0 0 0.0215" />
        <parent link="little_middle_link" />
        <child link="little_distal_link" />
        <axis xyz="1 0 0" />
        <limit effort="100" lower="0.0" upper="1.5707963267948966" velocity="100" />
        <dynamics damping="0.0" friction="0.0" />
    </joint>
    <link name="little_distal_link">
        <visual>
            <geometry>
                <mesh filename="package://human_arm_description/model/meshes/little_distal.stl" scale="0.001 0.001 0.001" />
            </geometry>
            <material name="HumanHand/Skin" />
        </visual>
    </link>
    <!-- TIP-->
    <joint name="little_ee_joint" type="fixed">
        <origin rpy="0 0 0" xyz="0 0 0.03" />
        <parent link="little_distal_link" />
        <child link="little_ee_link" />
    </joint>
    <link name="little_ee_link" />
    <transmission name="trans_elbow_joint">
        <type>transmission_interface/SimpleTransmission</type>
        <joint name="elbow_joint">
            <hardwareInterface>hardware_interface/EffortJointInterface</hardwareInterface>
        </joint>
        <actuator name="elbow_joint_motor">
            <hardwareInterface>hardware_interface/EffortJointInterface</hardwareInterface>
            <mechanicalReduction>1</mechanicalReduction>
        </actuator>
    </transmission>
    <transmission name="trans_distal_radioulnar_joint">
        <type>transmission_interface/SimpleTransmission</type>
        <joint name="distal_radioulnar_joint">
            <hardwareInterface>hardware_interface/EffortJointInterface</hardwareInterface>
        </joint>
        <actuator name="distal_radioulnar_joint_motor">
            <hardwareInterface>hardware_interface/EffortJointInterface</hardwareInterface>
            <mechanicalReduction>1</mechanicalReduction>
        </actuator>
    </transmission>
    <transmission name="trans_radiocarpal_abductor_joint">
        <type>transmission_interface/SimpleTransmission</type>
        <joint name="radiocarpal_abductor_joint">
            <hardwareInterface>hardware_interface/EffortJointInterface</hardwareInterface>
        </joint>
        <actuator name="radiocarpal_abductor_joint_motor">
            <hardwareInterface>hardware_interface/EffortJointInterface</hardwareInterface>
            <mechanicalReduction>1</mechanicalReduction>
        </actuator>
    </transmission>
    <transmission name="trans_radiocarpal_flexor_joint">
        <type>transmission_interface/SimpleTransmission</type>
        <joint name="radiocarpal_flexor_joint">
            <hardwareInterface>hardware_interface/EffortJointInterface</hardwareInterface>
        </joint>
        <actuator name="radiocarpal_flexor_joint_motor">
            <hardwareInterface>hardware_interface/EffortJointInterface</hardwareInterface>
            <mechanicalReduction>1</mechanicalReduction>
        </actuator>
    </transmission>
    <transmission name="trans_thumb_abduction_joint">
        <type>transmission_interface/SimpleTransmission</type>
        <joint name="thumb_abduction_joint">
            <hardwareInterface>hardware_interface/PositionJointInterface</hardwareInterface>
        </joint>
        <actuator name="thumb_abduction_joint_motor">
            <hardwareInterface>hardware_interface/PositionJointInterface</hardwareInterface>
            <mechanicalReduction>1</mechanicalReduction>
        </actuator>
    </transmission>
    <transmission name="trans_thumb_proximal_joint">
        <type>transmission_interface/SimpleTransmission</type>
        <joint name="thumb_proximal_joint">
            <hardwareInterface>hardware_interface/PositionJointInterface</hardwareInterface>
        </joint>
        <actuator name="thumb_proximal_joint_motor">
            <hardwareInterface>hardware_interface/PositionJointInterface</hardwareInterface>
            <mechanicalReduction>1</mechanicalReduction>
        </actuator>
    </transmission>
    <transmission name="trans_thumb_middle_joint">
        <type>transmission_interface/SimpleTransmission</type>
        <joint name="thumb_middle_joint">
            <hardwareInterface>hardware_interface/PositionJointInterface</hardwareInterface>
        </joint>
        <actuator name="thumb_middle_joint_motor">
            <hardwareInterface>hardware_interface/PositionJointInterface</hardwareInterface>
            <mechanicalReduction>1</mechanicalReduction>
        </actuator>
    </transmission>
    <transmission name="trans_thumb_distal_joint">
        <type>transmission_interface/SimpleTransmission</type>
        <joint name="thumb_distal_joint">
            <hardwareInterface>hardware_interface/PositionJointInterface</hardwareInterface>
        </joint>
        <actuator name="thumb_distal_joint_motor">
            <hardwareInterface>hardware_interface/PositionJointInterface</hardwareInterface>
            <mechanicalReduction>1</mechanicalReduction>
        </actuator>
    </transmission>
    <transmission name="trans_index_abduction_joint">
        <type>transmission_interface/SimpleTransmission</type>
        <joint name="index_abduction_joint">
            <hardwareInterface>hardware_interface/PositionJointInterface</hardwareInterface>
        </joint>
        <actuator name="index_abduction_joint_motor">
            <hardwareInterface>hardware_interface/PositionJointInterface</hardwareInterface>
            <mechanicalReduction>1</mechanicalReduction>
        </actuator>
    </transmission>
    <transmission name="trans_index_proximal_joint">
        <type>transmission_interface/SimpleTransmission</type>
        <joint name="index_proximal_joint">
            <hardwareInterface>hardware_interface/PositionJointInterface</hardwareInterface>
        </joint>
        <actuator name="index_proximal_joint_motor">
            <hardwareInterface>hardware_interface/PositionJointInterface</hardwareInterface>
            <mechanicalReduction>1</mechanicalReduction>
        </actuator>
    </transmission>
    <transmission name="trans_index_middle_joint">
        <type>transmission_interface/SimpleTransmission</type>
        <joint name="index_middle_joint">
            <hardwareInterface>hardware_interface/PositionJointInterface</hardwareInterface>
        </joint>
        <actuator name="index_middle_joint_motor">
            <hardwareInterface>hardware_interface/PositionJointInterface</hardwareInterface>
            <mechanicalReduction>1</mechanicalReduction>
        </actuator>
    </transmission>
    <transmission name="trans_index_distal_joint">
        <type>transmission_interface/SimpleTransmission</type>
        <joint name="index_distal_joint">
            <hardwareInterface>hardware_interface/PositionJointInterface</hardwareInterface>
        </joint>
        <actuator name="index_distal_joint_motor">
            <hardwareInterface>hardware_interface/PositionJointInterface</hardwareInterface>
            <mechanicalReduction>1</mechanicalReduction>
        </actuator>
    </transmission>
    <transmission name="trans_middle_abduction_joint">
        <type>transmission_interface/SimpleTransmission</type>
        <joint name="middle_abduction_joint">
            <hardwareInterface>hardware_interface/PositionJointInterface</hardwareInterface>
        </joint>
        <actuator name="middle_abduction_joint_motor">
            <hardwareInterface>hardware_interface/PositionJointInterface</hardwareInterface>
            <mechanicalReduction>1</mechanicalReduction>
        </actuator>
    </transmission>
    <transmission name="trans_middle_proximal_joint">
        <type>transmission_interface/SimpleTransmission</type>
        <joint name="middle_proximal_joint">
            <hardwareInterface>hardware_interface/PositionJointInterface</hardwareInterface>
        </joint>
        <actuator name="middle_proximal_joint_motor">
            <hardwareInterface>hardware_interface/PositionJointInterface</hardwareInterface>
            <mechanicalReduction>1</mechanicalReduction>
        </actuator>
    </transmission>
    <transmission name="trans_middle_middle_joint">
        <type>transmission_interface/SimpleTransmission</type>
        <joint name="middle_middle_joint">
            <hardwareInterface>hardware_interface/PositionJointInterface</hardwareInterface>
        </joint>
        <actuator name="middle_middle_joint_motor">
            <hardwareInterface>hardware_interface/PositionJointInterface</hardwareInterface>
            <mechanicalReduction>1</mechanicalReduction>
        </actuator>
    </transmission>
    <transmission name="trans_middle_distal_joint">
        <type>transmission_interface/SimpleTransmission</type>
        <joint name="middle_distal_joint">
            <hardwareInterface>hardware_interface/PositionJointInterface</hardwareInterface>
        </joint>
        <actuator name="middle_distal_joint_motor">
            <hardwareInterface>hardware_interface/PositionJointInterface</hardwareInterface>
            <mechanicalReduction>1</mechanicalReduction>
        </actuator>
    </transmission>
    <transmission name="trans_ring_abduction_joint">
        <type>transmission_interface/SimpleTransmission</type>
        <joint name="ring_abduction_joint">
            <hardwareInterface>hardware_interface/PositionJointInterface</hardwareInterface>
        </joint>
        <actuator name="ring_abduction_joint_motor">
            <hardwareInterface>hardware_interface/PositionJointInterface</hardwareInterface>
            <mechanicalReduction>1</mechanicalReduction>
        </actuator>
    </transmission>
    <transmission name="trans_ring_proximal_joint">
        <type>transmission_interface/SimpleTransmission</type>
        <joint name="ring_proximal_joint">
            <hardwareInterface>hardware_interface/PositionJointInterface</hardwareInterface>
        </joint>
        <actuator name="ring_proximal_joint_motor">
            <hardwareInterface>hardware_interface/PositionJointInterface</hardwareInterface>
            <mechanicalReduction>1</mechanicalReduction>
        </actuator>
    </transmission>
    <transmission name="trans_ring_middle_joint">
        <type>transmission_interface/SimpleTransmission</type>
        <joint name="ring_middle_joint">
            <hardwareInterface>hardware_interface/PositionJointInterface</hardwareInterface>
        </joint>
        <actuator name="ring_middle_joint_motor">
            <hardwareInterface>hardware_interface/PositionJointInterface</hardwareInterface>
            <mechanicalReduction>1</mechanicalReduction>
        </actuator>
    </transmission>
    <transmission name="trans_ring_distal_joint">
        <type>transmission_interface/SimpleTransmission</type>
        <joint name="ring_distal_joint">
            <hardwareInterface>hardware_interface/PositionJointInterface</hardwareInterface>
        </joint>
        <actuator name="ring_distal_joint_motor">
            <hardwareInterface>hardware_interface/PositionJointInterface</hardwareInterface>
            <mechanicalReduction>1</mechanicalReduction>
        </actuator>
    </transmission>
    <transmission name="trans_little_abduction_joint">
        <type>transmission_interface/SimpleTransmission</type>
        <joint name="little_abduction_joint">
            <hardwareInterface>hardware_interface/PositionJointInterface</hardwareInterface>
        </joint>
        <actuator name="little_abduction_joint_motor">
            <hardwareInterface>hardware_interface/PositionJointInterface</hardwareInterface>
            <mechanicalReduction>1</mechanicalReduction>
        </actuator>
    </transmission>
    <transmission name="trans_little_proximal_joint">
        <type>transmission_interface/SimpleTransmission</type>
        <joint name="little_proximal_joint">
            <hardwareInterface>hardware_interface/PositionJointInterface</hardwareInterface>
        </joint>
        <actuator name="little_proximal_joint_motor">
            <hardwareInterface>hardware_interface/PositionJointInterface</hardwareInterface>
            <mechanicalReduction>1</mechanicalReduction>
        </actuator>
    </transmission>
    <transmission name="trans_little_middle_joint">
        <type>transmission_interface/SimpleTransmission</type>
        <joint name="little_middle_joint">
            <hardwareInterface>hardware_interface/PositionJointInterface</hardwareInterface>
        </joint>
        <actuator name="little_middle_joint_motor">
            <hardwareInterface>hardware_interface/PositionJointInterface</hardwareInterface>
            <mechanicalReduction>1</mechanicalReduction>
        </actuator>
    </transmission>
    <transmission name="trans_little_distal_joint">
        <type>transmission_interface/SimpleTransmission</type>
        <joint name="little_distal_joint">
            <hardwareInterface>hardware_interface/PositionJointInterface</hardwareInterface>
        </joint>
        <actuator name="little_distal_joint_motor">
            <hardwareInterface>hardware_interface/PositionJointInterface</hardwareInterface>
            <mechanicalReduction>1</mechanicalReduction>
        </actuator>
    </transmission>
    <gazebo>
        <plugin name="gazebo_ros_control">
            <robotNamespace>/</robotNamespace>
        </plugin>
    </gazebo>
</robot>

